<?xml version="1.0"?>
<robot name="autonomous_mower">
  <link name="odom"/>

  <link name="base_link">
    <visual>
      <origin xyz="0 0 0.08" rpy="0 0 0"/>
      <geometry>
        <box size="0.70 0.52 0.16"/>
      </geometry>
    </visual>
  </link>

  <joint name="odom_to_base_link" type="fixed">
    <parent link="odom"/>
    <child link="base_link"/>
  </joint>

  <link name="left_wheel_link">
    <visual>
      <origin xyz="0 0 0" rpy="1.57079632679 0 0"/>
      <geometry>
        <cylinder radius="0.165" length="0.06"/>
      </geometry>
    </visual>
  </link>

  <link name="right_wheel_link">
    <visual>
      <origin xyz="0 0 0" rpy="1.57079632679 0 0"/>
      <geometry>
        <cylinder radius="0.165" length="0.06"/>
      </geometry>
    </visual>
  </link>

  <joint name="left_wheel_joint" type="continuous">
    <parent link="base_link"/>
    <child link="left_wheel_link"/>
    <origin xyz="0 0.26 0" rpy="0 0 0"/>
    <axis xyz="0 1 0"/>
  </joint>

  <joint name="right_wheel_joint" type="continuous">
    <parent link="base_link"/>
    <child link="right_wheel_link"/>
    <origin xyz="0 -0.26 0" rpy="0 0 0"/>
    <axis xyz="0 1 0"/>
  </joint>

  <ros2_control name="MowerBase" type="system">
    <hardware>
      <plugin>mower_base/MowerHardware</plugin>
      <param name="port">/dev/ttyACM0</param>
      <param name="baud">115200</param>
      <param name="counts_per_rev">205.0</param>
      <param name="max_pwm">60</param>
      <param name="max_wheel_rad_per_sec">8.0</param>
      <param name="read_timeout_ms">80</param>
    </hardware>

    <joint name="left_wheel_joint">
      <command_interface name="velocity"/>
      <state_interface name="position"/>
      <state_interface name="velocity"/>
    </joint>

    <joint name="right_wheel_joint">
      <command_interface name="velocity"/>
      <state_interface name="position"/>
      <state_interface name="velocity"/>
    </joint>
  </ros2_control>
</robot>
